Workbook
Name All_Currencies_Invested: Dashboard!$D$5:$D$36
Name Date_1: INDEX(Account_Value!$C$3:$C$2001,MATCH(Dashboard!$D$49,Account_Value!$C$3:$C$2001,0)):INDEX(Account_Value!$C$3:$C$2001,MATCH(Dashboard!$D$51,Account_Value!$C$3:$C$2001,0))
Name Date_2: INDEX(Account_Value!$N$3:$N$2001,MATCH(Dashboard!$D$49,Account_Value!$N$3:$N$2001,0)):INDEX(Account_Value!$N$3:$N$2001,MATCH(Dashboard!$D$51,Account_Value!$N$3:$N$2001,0))
Name Date_Market: Calculator!$D:$E
Name ETH_1: INDEX(Account_Value!$J$3:$J$2001,MATCH(Dashboard!$D$49,Account_Value!$I$3:$I$2001,0)):INDEX(Account_Value!$J$3:$J$2001,MATCH(Dashboard!$D$51,Account_Value!$I$3:$I$2001,0))
Name Profit_1: INDEX(Account_Value!$O$3:$O$2001,MATCH(Dashboard!$D$49,Account_Value!$N$3:$N$2001,0)):INDEX(Account_Value!$O$3:$O$2001,MATCH(Dashboard!$D$51,Account_Value!$N$3:$N$2001,0))
Name Values_1: INDEX(Account_Value!$D$3:$D$2001,MATCH(Dashboard!$D$49,Account_Value!$C$3:$C$2001,0)):INDEX(Account_Value!$D$3:$D$2001,MATCH(Dashboard!$D$51,Account_Value!$C$3:$C$2001,0))

Sheet Dashboard
AD2: Navigation
D3: Trade History | P3: Crypto Trading Dashboard v6b | X3: =TODAY() -> 44234
D4: Crypto | F4: Costs | H4: Sales | J4: Fees | L4: Profit | N4: Profit %
D5: =Calculator!$AM2 | F5: =IF($D5="","",Calculator!$AS2) | H5: =IF($D5="","",Calculator!$AT2) | J5: =IF($D5="","",Calculator!$AU2) | L5: =IF($D5="","",Calculator!$BC2) | N5: =IF(Calculator!$BA2="CURRENT","",IF($L5="","",$L5/$F5)) | P5: Current Investments
D6: =Calculator!$AM3 | F6: =IF($D6="","",Calculator!$AS3) | H6: =IF($D6="","",Calculator!$AT3) | J6: =IF($D6="","",Calculator!$AU3) | L6: =IF($D6="","",Calculator!$BC3) | N6: =IF(Calculator!$BA3="CURRENT","",IF($L6="","",$L6/$F6)) | Q6: Purchase | R6: Amount of | S6: Price | T6: Current | V6: Current
D7: =Calculator!$AM4 | F7: =IF($D7="","",Calculator!$AS4) | H7: =IF($D7="","",Calculator!$AT4) | J7: =IF($D7="","",Calculator!$AU4) | L7: =IF($D7="","",Calculator!$BC4) | N7: =IF(Calculator!$BA4="CURRENT","",IF($L7="","",$L7/$F7)) | P7: Currency | Q7: Date | R7: Coins | S7: Paid | T7: Price | U7: Cost | V7: Value | W7: Diff. | X7: % | Y7: 24 hr
D8: =Calculator!$AM5 | F8: =IF($D8="","",Calculator!$AS5) | H8: =IF($D8="","",Calculator!$AT5) | J8: =IF($D8="","",Calculator!$AU5) | L8: =IF($D8="","",Calculator!$BC5) | N8: =IF(Calculator!$BA5="CURRENT","",IF($L8="","",$L8/$F8)) | P8: USD | Q8: 44232 | R8: 0 | V8: =$R$8 -> 0
D9: =Calculator!$AM6 | F9: =IF($D9="","",Calculator!$AS6) | H9: =IF($D9="","",Calculator!$AT6) | J9: =IF($D9="","",Calculator!$AU6) | L9: =IF($D9="","",Calculator!$BC6) | N9: =IF(Calculator!$BA6="CURRENT","",IF($L9="","",$L9/$F9)) | R9: =IFERROR(VLOOKUP($P9,Calculator!$AM$2:$BD$50,12,0),"") | S9: =IFERROR(VLOOKUP($P9,Calculator!$AM$2:$BD$50,6,0),"") | T9: =IFERROR(VLOOKUP($P9,Calculator!$BS$2:$BU$50,3,0),"") | U9: =IFERROR($R9*$S9,"") | V9: =IFERROR($R9*$T9,"") | W9: =IFERROR($V9-$U9, "") | X9: =IFERROR($W9/$U9,"") | Y9: =IFERROR(VLOOKUP($P9,Calculator!$BS$2:$BW$50,5,0),"")
D10: =Calculator!$AM7 | F10: =IF($D10="","",Calculator!$AS7) | H10: =IF($D10="","",Calculator!$AT7) | J10: =IF($D10="","",Calculator!$AU7) | L10: =IF($D10="","",Calculator!$BC7) | N10: =IF(Calculator!$BA7="CURRENT","",IF($L10="","",$L10/$F10)) | R10: =IFERROR(VLOOKUP($P10,Calculator!$AM$2:$BD$50,12,0),"") | S10: =IFERROR(VLOOKUP($P10,Calculator!$AM$2:$BD$50,6,0),"") | T10: =IFERROR(VLOOKUP($P10,Calculator!$BS$2:$BU$50,3,0),"") | U10: =IFERROR($R10*$S10,"") | V10: =IFERROR($R10*$T10,"") | W10: =IFERROR($V10-$U10, "") | X10: =IFERROR($W10/$U10,"") | Y10: =IFERROR(VLOOKUP($P10,Calculator!$BS$2:$BW$50,5,0),"")
D11: =Calculator!$AM8 | F11: =IF($D11="","",Calculator!$AS8) | H11: =IF($D11="","",Calculator!$AT8) | J11: =IF($D11="","",Calculator!$AU8) | L11: =IF($D11="","",Calculator!$BC8) | N11: =IF(Calculator!$BA8="CURRENT","",IF($L11="","",$L11/$F11)) | R11: =IFERROR(VLOOKUP($P11,Calculator!$AM$2:$BD$50,12,0),"") | S11: =IFERROR(VLOOKUP($P11,Calculator!$AM$2:$BD$50,6,0),"") | T11: =IFERROR(VLOOKUP($P11,Calculator!$BS$2:$BU$50,3,0),"") | U11: =IFERROR($R11*$S11,"") | V11: =IFERROR($R11*$T11,"") | W11: =IFERROR($V11-$U11, "") | X11: =IFERROR($W11/$U11,"") | Y11: =IFERROR(VLOOKUP($P11,Calculator!$BS$2:$BW$50,5,0),"")
D12: =Calculator!$AM9 | F12: =IF($D12="","",Calculator!$AS9) | H12: =IF($D12="","",Calculator!$AT9) | J12: =IF($D12="","",Calculator!$AU9) | L12: =IF($D12="","",Calculator!$BC9) | N12: =IF(Calculator!$BA9="CURRENT","",IF($L12="","",$L12/$F12)) | R12: =IFERROR(VLOOKUP($P12,Calculator!$AM$2:$BD$50,12,0),"") | S12: =IFERROR(VLOOKUP($P12,Calculator!$AM$2:$BD$50,6,0),"") | T12: =IFERROR(VLOOKUP($P12,Calculator!$BS$2:$BU$50,3,0),"") | U12: =IFERROR($R12*$S12,"") | V12: =IFERROR($R12*$T12,"") | W12: =IFERROR($V12-$U12, "") | X12: =IFERROR($W12/$U12,"") | Y12: =IFERROR(VLOOKUP($P12,Calculator!$BS$2:$BW$50,5,0),"")
D13: =Calculator!$AM10 | F13: =IF($D13="","",Calculator!$AS10) | H13: =IF($D13="","",Calculator!$AT10) | J13: =IF($D13="","",Calculator!$AU10) | L13: =IF($D13="","",Calculator!$BC10) | N13: =IF(Calculator!$BA10="CURRENT","",IF($L13="","",$L13/$F13)) | R13: =IFERROR(VLOOKUP($P13,Calculator!$AM$2:$BD$50,12,0),"") | S13: =IFERROR(VLOOKUP($P13,Calculator!$AM$2:$BD$50,6,0),"") | T13: =IFERROR(VLOOKUP($P13,Calculator!$BS$2:$BU$50,3,0),"") | U13: =IFERROR($R13*$S13,"") | V13: =IFERROR($R13*$T13,"") | W13: =IFERROR($V13-$U13, "") | X13: =IFERROR($W13/$U13,"") | Y13: =IFERROR(VLOOKUP($P13,Calculator!$BS$2:$BW$50,5,0),"")
D14: =Calculator!$AM11 | F14: =IF($D14="","",Calculator!$AS11) | H14: =IF($D14="","",Calculator!$AT11) | J14: =IF($D14="","",Calculator!$AU11) | L14: =IF($D14="","",Calculator!$BC11) | N14: =IF(Calculator!$BA11="CURRENT","",IF($L14="","",$L14/$F14)) | R14: =IFERROR(VLOOKUP($P14,Calculator!$AM$2:$BD$50,12,0),"") | S14: =IFERROR(VLOOKUP($P14,Calculator!$AM$2:$BD$50,6,0),"") | T14: =IFERROR(VLOOKUP($P14,Calculator!$BS$2:$BU$50,3,0),"") | U14: =IFERROR($R14*$S14,"") | V14: =IFERROR($R14*$T14,"") | W14: =IFERROR($V14-$U14, "") | X14: =IFERROR($W14/$U14,"") | Y14: =IFERROR(VLOOKUP($P14,Calculator!$BS$2:$BW$50,5,0),"")
D15: =Calculator!$AM12 | F15: =IF($D15="","",Calculator!$AS12) | H15: =IF($D15="","",Calculator!$AT12) | J15: =IF($D15="","",Calculator!$AU12) | L15: =IF($D15="","",Calculator!$BC12) | N15: =IF(Calculator!$BA12="CURRENT","",IF($L15="","",$L15/$F15)) | R15: =IFERROR(VLOOKUP($P15,Calculator!$AM$2:$BD$50,12,0),"") | S15: =IFERROR(VLOOKUP($P15,Calculator!$AM$2:$BD$50,6,0),"") | T15: =IFERROR(VLOOKUP($P15,Calculator!$BS$2:$BU$50,3,0),"") | U15: =IFERROR($R15*$S15,"") | V15: =IFERROR($R15*$T15,"") | W15: =IFERROR($V15-$U15, "") | X15: =IFERROR($W15/$U15,"") | Y15: =IFERROR(VLOOKUP($P15,Calculator!$BS$2:$BW$50,5,0),"")
D16: =Calculator!$AM13 | F16: =IF($D16="","",Calculator!$AS13) | H16: =IF($D16="","",Calculator!$AT13) | J16: =IF($D16="","",Calculator!$AU13) | L16: =IF($D16="","",Calculator!$BC13) | N16: =IF(Calculator!$BA13="CURRENT","",IF($L16="","",$L16/$F16)) | R16: =IFERROR(VLOOKUP($P16,Calculator!$AM$2:$BD$50,12,0),"") | S16: =IFERROR(VLOOKUP($P16,Calculator!$AM$2:$BD$50,6,0),"") | T16: =IFERROR(VLOOKUP($P16,Calculator!$BS$2:$BU$50,3,0),"") | U16: =IFERROR($R16*$S16,"") | V16: =IFERROR($R16*$T16,"") | W16: =IFERROR($V16-$U16, "") | X16: =IFERROR($W16/$U16,"") | Y16: =IFERROR(VLOOKUP($P16,Calculator!$BS$2:$BW$50,5,0),"")
D17: =Calculator!$AM14 | F17: =IF($D17="","",Calculator!$AS14) | H17: =IF($D17="","",Calculator!$AT14) | J17: =IF($D17="","",Calculator!$AU14) | L17: =IF($D17="","",Calculator!$BC14) | N17: =IF(Calculator!$BA14="CURRENT","",IF($L17="","",$L17/$F17)) | R17: =IFERROR(VLOOKUP($P17,Calculator!$AM$2:$BD$50,12,0),"") | S17: =IFERROR(VLOOKUP($P17,Calculator!$AM$2:$BD$50,6,0),"") | T17: =IFERROR(VLOOKUP($P17,Calculator!$BS$2:$BU$50,3,0),"") | U17: =IFERROR($R17*$S17,"") | V17: =IFERROR($R17*$T17,"") | W17: =IFERROR($V17-$U17, "") | X17: =IFERROR($W17/$U17,"") | Y17: =IFERROR(VLOOKUP($P17,Calculator!$BS$2:$BW$50,5,0),"")
D18: =Calculator!$AM15 | F18: =IF($D18="","",Calculator!$AS15) | H18: =IF($D18="","",Calculator!$AT15) | J18: =IF($D18="","",Calculator!$AU15) | L18: =IF($D18="","",Calculator!$BC15) | N18: =IF(Calculator!$BA15="CURRENT","",IF($L18="","",$L18/$F18)) | R18: =IFERROR(VLOOKUP($P18,Calculator!$AM$2:$BD$50,12,0),"") | S18: =IFERROR(VLOOKUP($P18,Calculator!$AM$2:$BD$50,6,0),"") | T18: =IFERROR(VLOOKUP($P18,Calculator!$BS$2:$BU$50,3,0),"") | U18: =IFERROR($R18*$S18,"") | V18: =IFERROR($R18*$T18,"") | W18: =IFERROR($V18-$U18, "") | X18: =IFERROR($W18/$U18,"") | Y18: =IFERROR(VLOOKUP($P18,Calculator!$BS$2:$BW$50,5,0),"")
D19: =Calculator!$AM16 | F19: =IF($D19="","",Calculator!$AS16) | H19: =IF($D19="","",Calculator!$AT16) | J19: =IF($D19="","",Calculator!$AU16) | L19: =IF($D19="","",Calculator!$BC16) | N19: =IF(Calculator!$BA16="CURRENT","",IF($L19="","",$L19/$F19)) | P19: ETH | R19: =Calculator!$BQ$2 -> 0 | T19: =IFERROR(VLOOKUP($P19,Calculator!$BS$2:$BU$50,3,0),"") -> 1624.07 | V19: =IFERROR($R19*$T19,"") -> 0 | Y19: =IFERROR(VLOOKUP($P19,Calculator!$BS$2:$BW$50,5,0),"") -> -0.033941456
D20: =Calculator!$AM17 | F20: =IF($D20="","",Calculator!$AS17) | H20: =IF($D20="","",Calculator!$AT17) | J20: =IF($D20="","",Calculator!$AU17) | L20: =IF($D20="","",Calculator!$BC17) | N20: =IF(Calculator!$BA17="CURRENT","",IF($L20="","",$L20/$F20)) | R20: Cash | S20: ETH
D21: =Calculator!$AM18 | F21: =IF($D21="","",Calculator!$AS18) | H21: =IF($D21="","",Calculator!$AT18) | J21: =IF($D21="","",Calculator!$AU18) | L21: =IF($D21="","",Calculator!$BC18) | N21: =IF(Calculator!$BA18="CURRENT","",IF($L21="","",$L21/$F21)) | Q21: Account Deposits: | R21: =SUM(Account_Value!$E:$E) -> 0 | S21: =$Y$34 -> 0 | V21: Investment Data
D22: =Calculator!$AM19 | F22: =IF($D22="","",Calculator!$AS19) | H22: =IF($D22="","",Calculator!$AT19) | J22: =IF($D22="","",Calculator!$AU19) | L22: =IF($D22="","",Calculator!$BC19) | N22: =IF(Calculator!$BA19="CURRENT","",IF($L22="","",$L22/$F22)) | X22: Number of Transactions | Y22: =Calculator!$BN$2 -> 4.9515947e-14
D23: =Calculator!$AM20 | F23: =IF($D23="","",Calculator!$AS20) | H23: =IF($D23="","",Calculator!$AT20) | J23: =IF($D23="","",Calculator!$AU20) | L23: =IF($D23="","",Calculator!$BC20) | N23: =IF(Calculator!$BA20="CURRENT","",IF($L23="","",$L23/$F23)) | Q23: Account Value: | R23: =SUM(V8:V19) -> 0 | X23: from | Y23: =MIN(Calculator!$C:$C) -> 0
D24: =Calculator!$AM21 | F24: =IF($D24="","",Calculator!$AS21) | H24: =IF($D24="","",Calculator!$AT21) | J24: =IF($D24="","",Calculator!$AU21) | L24: =IF($D24="","",Calculator!$BC21) | N24: =IF(Calculator!$BA21="CURRENT","",IF($L24="","",$L24/$F24)) | X24: to | Y24: =MAX(Calculator!$C:$C) -> 0
D25: =Calculator!$AM22 | F25: =IF($D25="","",Calculator!$AS22) | H25: =IF($D25="","",Calculator!$AT22) | J25: =IF($D25="","",Calculator!$AU22) | L25: =IF($D25="","",Calculator!$BC22) | N25: =IF(Calculator!$BA22="CURRENT","",IF($L25="","",$L25/$F25)) | Q25: Account Gain/Loss: | R25: =$R$23-$R$21 -> 0 | S25: =IFERROR($R$25/$R$21,"") | X25: Cost of Sales | Y25: =IFERROR(Calculator!$BK$2,"$0") -> 0
D26: =Calculator!$AM23 | F26: =IF($D26="","",Calculator!$AS23) | H26: =IF($D26="","",Calculator!$AT23) | J26: =IF($D26="","",Calculator!$AU23) | L26: =IF($D26="","",Calculator!$BC23) | N26: =IF(Calculator!$BA23="CURRENT","",IF($L26="","",$L26/$F26)) | X26: Total Sales | Y26: =Calculator!$BJ$2 -> 0
D27: =Calculator!$AM24 | F27: =IF($D27="","",Calculator!$AS24) | H27: =IF($D27="","",Calculator!$AT24) | J27: =IF($D27="","",Calculator!$AU24) | L27: =IF($D27="","",Calculator!$BC24) | N27: =IF(Calculator!$BA24="CURRENT","",IF($L27="","",$L27/$F27)) | X27: Binance Fees | Y27: =Calculator!$BM$2 -> 0
D28: =Calculator!$AM25 | F28: =IF($D28="","",Calculator!$AS25) | H28: =IF($D28="","",Calculator!$AT25) | J28: =IF($D28="","",Calculator!$AU25) | L28: =IF($D28="","",Calculator!$BC25) | N28: =IF(Calculator!$BA25="CURRENT","",IF($L28="","",$L28/$F28)) | X28: Profit from Sales | Y28: =Calculator!$BL$2 -> 0
D29: =Calculator!$AM26 | F29: =IF($D29="","",Calculator!$AS26) | H29: =IF($D29="","",Calculator!$AT26) | J29: =IF($D29="","",Calculator!$AU26) | L29: =IF($D29="","",Calculator!$BC26) | N29: =IF(Calculator!$BA26="CURRENT","",IF($L29="","",$L29/$F29))
D30: =Calculator!$AM27 | F30: =IF($D30="","",Calculator!$AS27) | H30: =IF($D30="","",Calculator!$AT27) | J30: =IF($D30="","",Calculator!$AU27) | L30: =IF($D30="","",Calculator!$BC27) | N30: =IF(Calculator!$BA27="CURRENT","",IF($L30="","",$L30/$F30)) | V30: Ethereum Mining
D31: =Calculator!$AM28 | F31: =IF($D31="","",Calculator!$AS28) | H31: =IF($D31="","",Calculator!$AT28) | J31: =IF($D31="","",Calculator!$AU28) | L31: =IF($D31="","",Calculator!$BC28) | N31: =IF(Calculator!$BA28="CURRENT","",IF($L31="","",$L31/$F31)) | X31: Number of Deposits | Y31: =Calculator!$BO$2 -> 0
D32: =Calculator!$AM29 | F32: =IF($D32="","",Calculator!$AS29) | H32: =IF($D32="","",Calculator!$AT29) | J32: =IF($D32="","",Calculator!$AU29) | L32: =IF($D32="","",Calculator!$BC29) | N32: =IF(Calculator!$BA29="CURRENT","",IF($L32="","",$L32/$F32)) | X32: from | Y32: =MIN(Calculator!$V:$V) -> 0
D33: =Calculator!$AM30 | F33: =IF($D33="","",Calculator!$AS30) | H33: =IF($D33="","",Calculator!$AT30) | J33: =IF($D33="","",Calculator!$AU30) | L33: =IF($D33="","",Calculator!$BC30) | N33: =IF(Calculator!$BA30="CURRENT","",IF($L33="","",$L33/$F33)) | X33: to | Y33: =MAX(Calculator!$V:$V) -> 0
D34: =Calculator!$AM31 | F34: =IF($D34="","",Calculator!$AS31) | H34: =IF($D34="","",Calculator!$AT31) | J34: =IF($D34="","",Calculator!$AU31) | L34: =IF($D34="","",Calculator!$BC31) | N34: =IF(Calculator!$BA31="CURRENT","",IF($L34="","",$L34/$F34)) | X34: All ETH Mined | Y34: =SUM(Calculator!$CB:$CB) -> 0
D35: =Calculator!$AM32 | F35: =IF($D35="","",Calculator!$AS32) | H35: =IF($D35="","",Calculator!$AT32) | J35: =IF($D35="","",Calculator!$AU32) | L35: =IF($D35="","",Calculator!$BC32) | N35: =IF(Calculator!$BA32="CURRENT","",IF($L35="","",$L35/$F35)) | X35: Current ETH Value | Y35: =$V$19 -> 0
D36: =Calculator!$AM33 | F36: =IF($D36="","",Calculator!$AS33) | H36: =IF($D36="","",Calculator!$AT33) | J36: =IF($D36="","",Calculator!$AU33) | L36: =IF($D36="","",Calculator!$BC33) | N36: =IF(Calculator!$BA33="CURRENT","",IF($L36="","",$L36/$F36))
D46: Select Date Range
D47: for Charts
D48: From
D49: 44197
D50: To
...

Sheet Account_Value
B2: Days | C2: Date | D2: Account Value | E2: Cash Deposits | F2: ETH_Price | G2: ETH Deposits | H2: ETH_Dep_copy | I2: Date_3 | J2: Mined_Value | K2: Ttl_ETH_Value | L2: Ttl_Acct_Value | M2: Gain_Loss | N2: Date_2 | O2: Percent Profit
B3: 1 | C3: 44061 | G3: =IFERROR(VLOOKUP($C3,Calculator!$BY$2:$CB$2500,4,0),"") | H3: =$G3*1 -> #VALUE! | I3: =$C3 -> 44061 | J3: =IF($C3>(TODAY()),NA(),SUM($G$3:$G3)) -> 0 | K3: =IFERROR(VLOOKUP($C3,Calculator!$BY$2:$CD$2500,6,0),"") | L3: =IF($D3="","",$D3) | M3: =IF($D3="","",$L3-(Dashboard!$R$21-(SUM($E4:$E$224)))) | N3: 44061 | O3: =IF($D3="",NA(),($M3)/Dashboard!$R$21) -> #N/A
B4: =$B3+1 -> 2 | C4: =$C3+1 -> 44062 | G4: =IFERROR(VLOOKUP($C4,Calculator!$BY$2:$CB$2500,4,0),"") | H4: =$G4*1 -> #VALUE! | I4: =$C4 -> 44062 | J4: =IF($C4>(TODAY()),NA(),SUM($G$3:$G4)) -> 0 | K4: =IFERROR(VLOOKUP($C4,Calculator!$BY$2:$CD$2500,6,0),"") | L4: =IF($D4="","",$D4) | M4: =IF($D4="","",$L4-(Dashboard!$R$21-(SUM($E5:$E$224)))) | N4: =$C3+1 -> 44062 | O4: =IF($D4="",NA(),($M4)/Dashboard!$R$21) -> #N/A
B5: =$B4+1 -> 3 | C5: =$C4+1 -> 44063 | G5: =IFERROR(VLOOKUP($C5,Calculator!$BY$2:$CB$2500,4,0),"") | H5: =$G5*1 -> #VALUE! | I5: =$C5 -> 44063 | J5: =IF($C5>(TODAY()),NA(),SUM($G$3:$G5)) -> 0 | K5: =IFERROR(VLOOKUP($C5,Calculator!$BY$2:$CD$2500,6,0),"") | L5: =IF($D5="","",$D5) | M5: =IF($D5="","",$L5-(Dashboard!$R$21-(SUM($E6:$E$224)))) | N5: =$C4+1 -> 44063 | O5: =IF($D5="",NA(),($M5)/Dashboard!$R$21) -> #N/A
B6: =$B5+1 -> 4 | C6: =$C5+1 -> 44064 | G6: =IFERROR(VLOOKUP($C6,Calculator!$BY$2:$CB$2500,4,0),"") | H6: =$G6*1 -> #VALUE! | I6: =$C6 -> 44064 | J6: =IF($C6>(TODAY()),NA(),SUM($G$3:$G6)) -> 0 | K6: =IFERROR(VLOOKUP($C6,Calculator!$BY$2:$CD$2500,6,0),"") | L6: =IF($D6="","",$D6) | M6: =IF($D6="","",$L6-(Dashboard!$R$21-(SUM($E7:$E$224)))) | N6: =$C5+1 -> 44064 | O6: =IF($D6="",NA(),($M6)/Dashboard!$R$21) -> #N/A
B7: =$B6+1 -> 5 | C7: =$C6+1 -> 44065 | G7: =IFERROR(VLOOKUP($C7,Calculator!$BY$2:$CB$2500,4,0),"") | H7: =$G7*1 -> #VALUE! | I7: =$C7 -> 44065 | J7: =IF($C7>(TODAY()),NA(),SUM($G$3:$G7)) -> 0 | K7: =IFERROR(VLOOKUP($C7,Calculator!$BY$2:$CD$2500,6,0),"") | L7: =IF($D7="","",$D7) | M7: =IF($D7="","",$L7-(Dashboard!$R$21-(SUM($E8:$E$224)))) | N7: =$C6+1 -> 44065 | O7: =IF($D7="",NA(),($M7)/Dashboard!$R$21) -> #N/A
B8: =$B7+1 -> 6 | C8: =$C7+1 -> 44066 | G8: =IFERROR(VLOOKUP($C8,Calculator!$BY$2:$CB$2500,4,0),"") | H8: =$G8*1 -> #VALUE! | I8: =$C8 -> 44066 | J8: =IF($C8>(TODAY()),NA(),SUM($G$3:$G8)) -> 0 | K8: =IFERROR(VLOOKUP($C8,Calculator!$BY$2:$CD$2500,6,0),"") | L8: =IF($D8="","",$D8) | M8: =IF($D8="","",$L8-(Dashboard!$R$21-(SUM($E9:$E$224)))) | N8: =$C7+1 -> 44066 | O8: =IF($D8="",NA(),($M8)/Dashboard!$R$21) -> #N/A
B9: =$B8+1 -> 7 | C9: =$C8+1 -> 44067 | G9: =IFERROR(VLOOKUP($C9,Calculator!$BY$2:$CB$2500,4,0),"") | H9: =$G9*1 -> #VALUE! | I9: =$C9 -> 44067 | J9: =IF($C9>(TODAY()),NA(),SUM($G$3:$G9)) -> 0 | K9: =IFERROR(VLOOKUP($C9,Calculator!$BY$2:$CD$2500,6,0),"") | L9: =IF($D9="","",$D9) | M9: =IF($D9="","",$L9-(Dashboard!$R$21-(SUM($E10:$E$224)))) | N9: =$C8+1 -> 44067 | O9: =IF($D9="",NA(),($M9)/Dashboard!$R$21) -> #N/A
B10: =$B9+1 -> 8 | C10: =$C9+1 -> 44068 | G10: =IFERROR(VLOOKUP($C10,Calculator!$BY$2:$CB$2500,4,0),"") | H10: =$G10*1 -> #VALUE! | I10: =$C10 -> 44068 | J10: =IF($C10>(TODAY()),NA(),SUM($G$3:$G10)) -> 0 | K10: =IFERROR(VLOOKUP($C10,Calculator!$BY$2:$CD$2500,6,0),"") | L10: =IF($D10="","",$D10) | M10: =IF($D10="","",$L10-(Dashboard!$R$21-(SUM($E11:$E$224)))) | N10: =$C9+1 -> 44068 | O10: =IF($D10="",NA(),($M10)/Dashboard!$R$21) -> #N/A
B11: =$B10+1 -> 9 | C11: =$C10+1 -> 44069 | G11: =IFERROR(VLOOKUP($C11,Calculator!$BY$2:$CB$2500,4,0),"") | H11: =$G11*1 -> #VALUE! | I11: =$C11 -> 44069 | J11: =IF($C11>(TODAY()),NA(),SUM($G$3:$G11)) -> 0 | K11: =IFERROR(VLOOKUP($C11,Calculator!$BY$2:$CD$2500,6,0),"") | L11: =IF($D11="","",$D11) | M11: =IF($D11="","",$L11-(Dashboard!$R$21-(SUM($E12:$E$224)))) | N11: =$C10+1 -> 44069 | O11: =IF($D11="",NA(),($M11)/Dashboard!$R$21) -> #N/A
B12: =$B11+1 -> 10 | C12: =$C11+1 -> 44070 | G12: =IFERROR(VLOOKUP($C12,Calculator!$BY$2:$CB$2500,4,0),"") | H12: =$G12*1 -> #VALUE! | I12: =$C12 -> 44070 | J12: =IF($C12>(TODAY()),NA(),SUM($G$3:$G12)) -> 0 | K12: =IFERROR(VLOOKUP($C12,Calculator!$BY$2:$CD$2500,6,0),"") | L12: =IF($D12="","",$D12) | M12: =IF($D12="","",$L12-(Dashboard!$R$21-(SUM($E13:$E$224)))) | N12: =$C11+1 -> 44070 | O12: =IF($D12="",NA(),($M12)/Dashboard!$R$21) -> #N/A
B13: =$B12+1 -> 11 | C13: =$C12+1 -> 44071 | G13: =IFERROR(VLOOKUP($C13,Calculator!$BY$2:$CB$2500,4,0),"") | H13: =$G13*1 -> #VALUE! | I13: =$C13 -> 44071 | J13: =IF($C13>(TODAY()),NA(),SUM($G$3:$G13)) -> 0 | K13: =IFERROR(VLOOKUP($C13,Calculator!$BY$2:$CD$2500,6,0),"") | L13: =IF($D13="","",$D13) | M13: =IF($D13="","",$L13-(Dashboard!$R$21-(SUM($E14:$E$224)))) | N13: =$C12+1 -> 44071 | O13: =IF($D13="",NA(),($M13)/Dashboard!$R$21) -> #N/A
B14: =$B13+1 -> 12 | C14: =$C13+1 -> 44072 | G14: =IFERROR(VLOOKUP($C14,Calculator!$BY$2:$CB$2500,4,0),"") | H14: =$G14*1 -> #VALUE! | I14: =$C14 -> 44072 | J14: =IF($C14>(TODAY()),NA(),SUM($G$3:$G14)) -> 0 | K14: =IFERROR(VLOOKUP($C14,Calculator!$BY$2:$CD$2500,6,0),"") | L14: =IF($D14="","",$D14) | M14: =IF($D14="","",$L14-(Dashboard!$R$21-(SUM($E15:$E$224)))) | N14: =$C13+1 -> 44072 | O14: =IF($D14="",NA(),($M14)/Dashboard!$R$21) -> #N/A
B15: =$B14+1 -> 13 | C15: =$C14+1 -> 44073 | G15: =IFERROR(VLOOKUP($C15,Calculator!$BY$2:$CB$2500,4,0),"") | H15: =$G15*1 -> #VALUE! | I15: =$C15 -> 44073 | J15: =IF($C15>(TODAY()),NA(),SUM($G$3:$G15)) -> 0 | K15: =IFERROR(VLOOKUP($C15,Calculator!$BY$2:$CD$2500,6,0),"") | L15: =IF($D15="","",$D15) | M15: =IF($D15="","",$L15-(Dashboard!$R$21-(SUM($E16:$E$224)))) | N15: =$C14+1 -> 44073 | O15: =IF($D15="",NA(),($M15)/Dashboard!$R$21) -> #N/A
... B116: =$B115+1 -> 114 | C116: =$C115+1 -> 44174 | G116: =IFERROR(VLOOKUP($C116,Calculator!$BY$2:$CB$2500,4,0),"") | H116: =$G116*1 -> #VALUE! | I116: =$C116 -> 44174 | J116: =IF($C116>(TODAY()),NA(),SUM($G$3:$G116)) -> 0 | K116: =IFERROR(VLOOKUP($C116,Calculator!$BY$2:$CD$2500,6,0),"") | L116: =IF($D116="","",$D116) | M116: =IF($D116="","",$L116-(Dashboard!$R$21-(SUM($E117:$E$224)))) | N116: =$C115+1 -> 44174 | O116: =IF($D116="",NA(),($M116)/Dashboard!$R$21) -> #N/A
B117: =$B116+1 -> 115 | C117: =$C116+1 -> 44175 | F117: 559.68 | G117: =IFERROR(VLOOKUP($C117,Calculator!$BY$2:$CB$2500,4,0),"") | H117: =$G117*1 -> #VALUE! | I117: =$C117 -> 44175 | J117: =IF($C117>(TODAY()),NA(),SUM($G$3:$G117)) -> 0 | K117: =IFERROR(VLOOKUP($C117,Calculator!$BY$2:$CD$2500,6,0),"") | L117: =IF($D117="","",$D117) | M117: =IF($D117="","",$L117-(Dashboard!$R$21-(SUM($E118:$E$224)))) | N117: =$C116+1 -> 44175 | O117: =IF($D117="",NA(),($M117)/Dashboard!$R$21) -> #N/A
B118: =$B117+1 -> 116 | C118: =$C117+1 -> 44176 | G118: =IFERROR(VLOOKUP($C118,Calculator!$BY$2:$CB$2500,4,0),"") | H118: =$G118*1 -> #VALUE! | I118: =$C118 -> 44176 | J118: =IF($C118>(TODAY()),NA(),SUM($G$3:$G118)) -> 0 | K118: =IFERROR(VLOOKUP($C118,Calculator!$BY$2:$CD$2500,6,0),"") | L118: =IF($D118="","",$D118) | M118: =IF($D118="","",$L118-(Dashboard!$R$21-(SUM($E119:$E$224)))) | N118: =$C117+1 -> 44176 | O118: =IF($D118="",NA(),($M118)/Dashboard!$R$21) -> #N/A
B119: =$B118+1 -> 117 | C119: =$C118+1 -> 44177 | G119: =IFERROR(VLOOKUP($C119,Calculator!$BY$2:$CB$2500,4,0),"") | H119: =$G119*1 -> #VALUE! | I119: =$C119 -> 44177 | J119: =IF($C119>(TODAY()),NA(),SUM($G$3:$G119)) -> 0 | K119: =IFERROR(VLOOKUP($C119,Calculator!$BY$2:$CD$2500,6,0),"") | L119: =IF($D119="","",$D119) | M119: =IF($D119="","",$L119-(Dashboard!$R$21-(SUM($E120:$E$224)))) | N119: =$C118+1 -> 44177 | O119: =IF($D119="",NA(),($M119)/Dashboard!$R$21) -> #N/A
B120: =$B119+1 -> 118 | C120: =$C119+1 -> 44178 | G120: =IFERROR(VLOOKUP($C120,Calculator!$BY$2:$CB$2500,4,0),"") | H120: =$G120*1 -> #VALUE! | I120: =$C120 -> 44178 | J120: =IF($C120>(TODAY()),NA(),SUM($G$3:$G120)) -> 0 | K120: =IFERROR(VLOOKUP($C120,Calculator!$BY$2:$CD$2500,6,0),"") | L120: =IF($D120="","",$D120) | M120: =IF($D120="","",$L120-(Dashboard!$R$21-(SUM($E121:$E$224)))) | N120: =$C119+1 -> 44178 | O120: =IF($D120="",NA(),($M120)/Dashboard!$R$21) -> #N/A
B121: =$B120+1 -> 119 | C121: =$C120+1 -> 44179 | G121: =IFERROR(VLOOKUP($C121,Calculator!$BY$2:$CB$2500,4,0),"") | H121: =$G121*1 -> #VALUE! | I121: =$C121 -> 44179 | J121: =IF($C121>(TODAY()),NA(),SUM($G$3:$G121)) -> 0 | K121: =IFERROR(VLOOKUP($C121,Calculator!$BY$2:$CD$2500,6,0),"") | L121: =IF($D121="","",$D121) | M121: =IF($D121="","",$L121-(Dashboard!$R$21-(SUM($E122:$E$224)))) | N121: =$C120+1 -> 44179 | O121: =IF($D121="",NA(),($M121)/Dashboard!$R$21) -> #N/A
B122: =$B121+1 -> 120 | C122: =$C121+1 -> 44180 | G122: =IFERROR(VLOOKUP($C122,Calculator!$BY$2:$CB$2500,4,0),"") | H122: =$G122*1 -> #VALUE! | I122: =$C122 -> 44180 | J122: =IF($C122>(TODAY()),NA(),SUM($G$3:$G122)) -> 0 | K122: =IFERROR(VLOOKUP($C122,Calculator!$BY$2:$CD$2500,6,0),"") | L122: =IF($D122="","",$D122) | M122: =IF($D122="","",$L122-(Dashboard!$R$21-(SUM($E123:$E$224)))) | N122: =$C121+1 -> 44180 | O122: =IF($D122="",NA(),($M122)/Dashboard!$R$21) -> #N/A
B123: =$B122+1 -> 121 | C123: =$C122+1 -> 44181 | G123: =IFERROR(VLOOKUP($C123,Calculator!$BY$2:$CB$2500,4,0),"") | H123: =$G123*1 -> #VALUE! | I123: =$C123 -> 44181 | J123: =IF($C123>(TODAY()),NA(),SUM($G$3:$G123)) -> 0 | K123: =IFERROR(VLOOKUP($C123,Calculator!$BY$2:$CD$2500,6,0),"") | L123: =IF($D123="","",$D123) | M123: =IF($D123="","",$L123-(Dashboard!$R$21-(SUM($E124:$E$224)))) | N123: =$C122+1 -> 44181 | O123: =IF($D123="",NA(),($M123)/Dashboard!$R$21) -> #N/A
B124: =$B123+1 -> 122 | C124: =$C123+1 -> 44182 | G124: =IFERROR(VLOOKUP($C124,Calculator!$BY$2:$CB$2500,4,0),"") | H124: =$G124*1 -> #VALUE! | I124: =$C124 -> 44182 | J124: =IF($C124>(TODAY()),NA(),SUM($G$3:$G124)) -> 0 | K124: =IFERROR(VLOOKUP($C124,Calculator!$BY$2:$CD$2500,6,0),"") | L124: =IF($D124="","",$D124) | M124: =IF($D124="","",$L124-(Dashboard!$R$21-(SUM($E125:$E$224)))) | N124: =$C123+1 -> 44182 | O124: =IF($D124="",NA(),($M124)/Dashboard!$R$21) -> #N/A
B125: =$B124+1 -> 123 | C125: =$C124+1 -> 44183 | G125: =IFERROR(VLOOKUP($C125,Calculator!$BY$2:$CB$2500,4,0),"") | H125: =$G125*1 -> #VALUE! | I125: =$C125 -> 44183 | J125: =IF($C125>(TODAY()),NA(),SUM($G$3:$G125)) -> 0 | K125: =IFERROR(VLOOKUP($C125,Calculator!$BY$2:$CD$2500,6,0),"") | L125: =IF($D125="","",$D125) | M125: =IF($D125="","",$L125-(Dashboard!$R$21-(SUM($E126:$E$224)))) | N125: =$C124+1 -> 44183 | O125: =IF($D125="",NA(),($M125)/Dashboard!$R$21) -> #N/A
B126: =$B125+1 -> 124 | C126: =$C125+1 -> 44184 | G126: =IFERROR(VLOOKUP($C126,Calculator!$BY$2:$CB$2500,4,0),"") | H126: =$G126*1 -> #VALUE! | I126: =$C126 -> 44184 | J126: =IF($C126>(TODAY()),NA(),SUM($G$3:$G126)) -> 0 | K126: =IFERROR(VLOOKUP($C126,Calculator!$BY$2:$CD$2500,6,0),"") | L126: =IF($D126="","",$D126) | M126: =IF($D126="","",$L126-(Dashboard!$R$21-(SUM($E127:$E$224)))) | N126: =$C125+1 -> 44184 | O126: =IF($D126="",NA(),($M126)/Dashboard!$R$21) -> #N/A
B127: =$B126+1 -> 125 | C127: =$C126+1 -> 44185 | G127: =IFERROR(VLOOKUP($C127,Calculator!$BY$2:$CB$2500,4,0),"") | H127: =$G127*1 -> #VALUE! | I127: =$C127 -> 44185 | J127: =IF($C127>(TODAY()),NA(),SUM($G$3:$G127)) -> 0 | K127: =IFERROR(VLOOKUP($C127,Calculator!$BY$2:$CD$2500,6,0),"") | L127: =IF($D127="","",$D127) | M127: =IF($D127="","",$L127-(Dashboard!$R$21-(SUM($E128:$E$224)))) | N127: =$C126+1 -> 44185 | O127: =IF($D127="",NA(),($M127)/Dashboard!$R$21) -> #N/A
B128: =$B127+1 -> 126 | C128: =$C127+1 -> 44186 | G128: =IFERROR(VLOOKUP($C128,Calculator!$BY$2:$CB$2500,4,0),"") | H128: =$G128*1 -> #VALUE! | I128: =$C128 -> 44186 | J128: =IF($C128>(TODAY()),NA(),SUM($G$3:$G128)) -> 0 | K128: =IFERROR(VLOOKUP($C128,Calculator!$BY$2:$CD$2500,6,0),"") | L128: =IF($D128="","",$D128) | M128: =IF($D128="","",$L128-(Dashboard!$R$21-(SUM($E129:$E$224)))) | N128: =$C127+1 -> 44186 | O128: =IF($D128="",NA(),($M128)/Dashboard!$R$21) -> #N/A
B129: =$B128+1 -> 127 | C129: =$C128+1 -> 44187 | G129: =IFERROR(VLOOKUP($C129,Calculator!$BY$2:$CB$2500,4,0),"") | H129: =$G129*1 -> #VALUE! | I129: =$C129 -> 44187 | J129: =IF($C129>(TODAY()),NA(),SUM($G$3:$G129)) -> 0 | K129: =IFERROR(VLOOKUP($C129,Calculator!$BY$2:$CD$2500,6,0),"") | L129: =IF($D129="","",$D129) | M129: =IF($D129="","",$L129-(Dashboard!$R$21-(SUM($E130:$E$224)))) | N129: =$C128+1 -> 44187 | O129: =IF($D129="",NA(),($M129)/Dashboard!$R$21) -> #N/A
... B223: =$B222+1 -> 221 | C223: =$C222+1 -> 44281 | G223: =IFERROR(VLOOKUP($C223,Calculator!$BY$2:$CB$2500,4,0),"") | H223: =$G223*1 -> #VALUE! | I223: =$C223 -> 44281 | J223: =IF($C223>(TODAY()),NA(),SUM($G$3:$G223)) -> #N/A | K223: =IFERROR(VLOOKUP($C223,Calculator!$BY$2:$CD$2500,6,0),"") | L223: =IF($D223="","",$D223) | M223: =IF($D223="","",$L223-(Dashboard!$R$21-(SUM($E224:$E$224)))) | N223: =$C222+1 -> 44281 | O223: =IF($D223="",NA(),($M223)/Dashboard!$R$21) -> #N/A
B224: =$B223+1 -> 222 | C224: =$C223+1 -> 44282 | G224: =IFERROR(VLOOKUP($C224,Calculator!$BY$2:$CB$2500,4,0),"") | H224: =$G224*1 -> #VALUE! | I224: =$C224 -> 44282 | J224: =IF($C224>(TODAY()),NA(),SUM($G$3:$G224)) -> #N/A | K224: =IFERROR(VLOOKUP($C224,Calculator!$BY$2:$CD$2500,6,0),"") | L224: =IF($D224="","",$D224) | M224: =IF($D224="","",$L224-(Dashboard!$R$21-(SUM($E$224:$E225)))) | N224: =$C223+1 -> 44282 | O224: =IF($D224="",NA(),($M224)/Dashboard!$R$21) -> #N/A
B225: =$B224+1 -> 223 | C225: =$C224+1 -> 44283 | G225: =IFERROR(VLOOKUP($C225,Calculator!$BY$2:$CB$2500,4,0),"") | H225: =$G225*1 -> #VALUE! | I225: =$C225 -> 44283 | J225: =IF($C225>(TODAY()),NA(),SUM($G$3:$G225)) -> #N/A | K225: =IFERROR(VLOOKUP($C225,Calculator!$BY$2:$CD$2500,6,0),"") | L225: =IF($D225="","",$D225) | M225: =IF($D225="","",$L225-(Dashboard!$R$21-(SUM($E$224:$E226)))) | N225: =$C224+1 -> 44283 | O225: =IF($D225="",NA(),($M225)/Dashboard!$R$21) -> #N/A
B226: =$B225+1 -> 224 | C226: =$C225+1 -> 44284 | G226: =IFERROR(VLOOKUP($C226,Calculator!$BY$2:$CB$2500,4,0),"") | H226: =$G226*1 -> #VALUE! | I226: =$C226 -> 44284 | J226: =IF($C226>(TODAY()),NA(),SUM($G$3:$G226)) -> #N/A | K226: =IFERROR(VLOOKUP($C226,Calculator!$BY$2:$CD$2500,6,0),"") | L226: =IF($D226="","",$D226) | M226: =IF($D226="","",$L226-(Dashboard!$R$21-(SUM($E$224:$E227)))) | N226: =$C225+1 -> 44284 | O226: =IF($D226="",NA(),($M226)/Dashboard!$R$21) -> #N/A
B227: =$B226+1 -> 225 | C227: =$C226+1 -> 44285 | G227: =IFERROR(VLOOKUP($C227,Calculator!$BY$2:$CB$2500,4,0),"") | H227: =$G227*1 -> #VALUE! | I227: =$C227 -> 44285 | J227: =IF($C227>(TODAY()),NA(),SUM($G$3:$G227)) -> #N/A | K227: =IFERROR(VLOOKUP($C227,Calculator!$BY$2:$CD$2500,6,0),"") | L227: =IF($D227="","",$D227) | M227: =IF($D227="","",$L227-(Dashboard!$R$21-(SUM($E$224:$E228)))) | N227: =$C226+1 -> 44285 | O227: =IF($D227="",NA(),($M227)/Dashboard!$R$21) -> #N/A
B228: =$B227+1 -> 226 | C228: =$C227+1 -> 44286 | G228: =IFERROR(VLOOKUP($C228,Calculator!$BY$2:$CB$2500,4,0),"") | H228: =$G228*1 -> #VALUE! | I228: =$C228 -> 44286 | J228: =IF($C228>(TODAY()),NA(),SUM($G$3:$G228)) -> #N/A | K228: =IFERROR(VLOOKUP($C228,Calculator!$BY$2:$CD$2500,6,0),"") | L228: =IF($D228="","",$D228) | M228: =IF($D228="","",$L228-(Dashboard!$R$21-(SUM($E$224:$E229)))) | N228: =$C227+1 -> 44286 | O228: =IF($D228="",NA(),($M228)/Dashboard!$R$21) -> #N/A
B229: =$B228+1 -> 227 | C229: =$C228+1 -> 44287 | G229: =IFERROR(VLOOKUP($C229,Calculator!$BY$2:$CB$2500,4,0),"") | H229: =$G229*1 -> #VALUE! | I229: =$C229 -> 44287 | J229: =IF($C229>(TODAY()),NA(),SUM($G$3:$G229)) -> #N/A | K229: =IFERROR(VLOOKUP($C229,Calculator!$BY$2:$CD$2500,6,0),"") | L229: =IF($D229="","",$D229) | M229: =IF($D229="","",$L229-(Dashboard!$R$21-(SUM($E$224:$E230)))) | N229: =$C228+1 -> 44287 | O229: =IF($D229="",NA(),($M229)/Dashboard!$R$21) -> #N/A
B230: =$B229+1 -> 228 | C230: =$C229+1 -> 44288 | G230: =IFERROR(VLOOKUP($C230,Calculator!$BY$2:$CB$2500,4,0),"") | H230: =$G230*1 -> #VALUE! | I230: =$C230 -> 44288 | J230: =IF($C230>(TODAY()),NA(),SUM($G$3:$G230)) -> #N/A | K230: =IFERROR(VLOOKUP($C230,Calculator!$BY$2:$CD$2500,6,0),"") | L230: =IF($D230="","",$D230) | M230: =IF($D230="","",$L230-(Dashboard!$R$21-(SUM($E$224:$E231)))) | N230: =$C229+1 -> 44288 | O230: =IF($D230="",NA(),($M230)/Dashboard!$R$21) -> #N/A
B231: =$B230+1 -> 229 | C231: =$C230+1 -> 44289 | G231: =IFERROR(VLOOKUP($C231,Calculator!$BY$2:$CB$2500,4,0),"") | H231: =$G231*1 -> #VALUE! | I231: =$C231 -> 44289 | J231: =IF($C231>(TODAY()),NA(),SUM($G$3:$G231)) -> #N/A | K231: =IFERROR(VLOOKUP($C231,Calculator!$BY$2:$CD$2500,6,0),"") | L231: =IF($D231="","",$D231) | M231: =IF($D231="","",$L231-(Dashboard!$R$21-(SUM($E$224:$E232)))) | N231: =$C230+1 -> 44289 | O231: =IF($D231="",NA(),($M231)/Dashboard!$R$21) -> #N/A
B232: =$B231+1 -> 230 | C232: =$C231+1 -> 44290 | G232: =IFERROR(VLOOKUP($C232,Calculator!$BY$2:$CB$2500,4,0),"") | H232: =$G232*1 -> #VALUE! | I232: =$C232 -> 44290 | J232: =IF($C232>(TODAY()),NA(),SUM($G$3:$G232)) -> #N/A | K232: =IFERROR(VLOOKUP($C232,Calculator!$BY$2:$CD$2500,6,0),"") | L232: =IF($D232="","",$D232) | M232: =IF($D232="","",$L232-(Dashboard!$R$21-(SUM($E$224:$E233)))) | N232: =$C231+1 -> 44290 | O232: =IF($D232="",NA(),($M232)/Dashboard!$R$21) -> #N/A
B233: =$B232+1 -> 231 | C233: =$C232+1 -> 44291 | G233: =IFERROR(VLOOKUP($C233,Calculator!$BY$2:$CB$2500,4,0),"") | H233: =$G233*1 -> #VALUE! | I233: =$C233 -> 44291 | J233: =IF($C233>(TODAY()),NA(),SUM($G$3:$G233)) -> #N/A | K233: =IFERROR(VLOOKUP($C233,Calculator!$BY$2:$CD$2500,6,0),"") | L233: =IF($D233="","",$D233) | M233: =IF($D233="","",$L233-(Dashboard!$R$21-(SUM($E$224:$E234)))) | N233: =$C232+1 -> 44291 | O233: =IF($D233="",NA(),($M233)/Dashboard!$R$21) -> #N/A
B234: =$B233+1 -> 232 | C234: =$C233+1 -> 44292 | G234: =IFERROR(VLOOKUP($C234,Calculator!$BY$2:$CB$2500,4,0),"") | H234: =$G234*1 -> #VALUE! | I234: =$C234 -> 44292 | J234: =IF($C234>(TODAY()),NA(),SUM($G$3:$G234)) -> #N/A | K234: =IFERROR(VLOOKUP($C234,Calculator!$BY$2:$CD$2500,6,0),"") | L234: =IF($D234="","",$D234) | M234: =IF($D234="","",$L234-(Dashboard!$R$21-(SUM($E$224:$E235)))) | N234: =$C233+1 -> 44292 | O234: =IF($D234="",NA(),($M234)/Dashboard!$R$21) -> #N/A
...

Sheet Calculator
A1: 1 | B1: Date(UTC) | C1: Date(2) | D1: Date(3) | E1: Market | F1: Date_Currency(1) | G1: Assign_Duplicates | H1: Date_Currency(3) | I1: Type | J1: Price | K1: Price(2) | L1: Amount | M1: Amount_2 | N1: Total | O1: Total$ | P1: Fee | Q1: Fee Coin | R1: Fee$1 | S1: Fee$2 | U1: Mining_Deposit | V1: Mining_Deposit_Date | W1: Mining_Date | X1: Date_Value | Y1: Date_Mod | Z1: Mining_Coin | AA1: Mining_Amount | AB1: Mining_Amount_Mod | AC1: Mined_Recent | AD1: Current_Value | AE1: Mining_Transaction_Fee | AF1: Mining_Address | AG1: Mining_TXID | AH1: Mining_Source_Address | AI1: Mining_Payment_ID | AJ1: Mining_Status | AL1: Unique Currencies | AM1: Short Name | AN1: Most Recent Purchase | AO1: Date_Currency(2) | AP1: Copy | AQ1: Price(3) | AR1: Price(4) | AS1: Total_Costs | AT1: Total_Sales | AU1: Total_Fees | AV1: Amount_Bought | AW1: Amount_Sold | AX1: Amount_Owned | AY1: Currency | AZ1: Current_Check_Amount_Owned | BA1: Current_Investments | BB1: Previous_Costs | BC1: Profit | BD1: Costs_of_Owned | BF1: Dashboard_Current | BG1: =$BF1 & " Revised" -> Dashboard_Current Revised | BH1: Mod | BI1: Total Costs | BJ1: Total Sales | BK1: Cost of Sales | BL1: Profit from Sales | BM1: Total Fees | BN1: Transactions | BO1: Mining_Deposits | BP1: Mined_ETH_Total | BQ1: Currently_Mined | BR1: coinmarketcap.com_prices | BS1: Crypto | BT1: Symbol | BU1: Current_Prices | BV1: CoinMarket_Prices | BW1: 24hr_Change | BY1: Date_ETH_Mined | BZ1: Mined_Amount | CA1: Price_on_mining_date | CB1: Mined_Value | CC1: Total_Mined | CD1: ETH_Ttl_Value
A2: =IF($B2="","",$A1+1) | B2: =IF(Investments_Import!A2="","",Investments_Import!A2) | C2: =IF(B2="","",B2*1) | D2: =$C2 | E2: =IF(Investments_Import!B2="","",Investments_Import!B2) | F2: =CONCATENATE(TEXT($D2,"dd-mmm-yyyy")," ",$E2) | G2: =IF($B2="","",COUNTIF($F$2:$F2,$F2)) | H2: =CONCATENATE(TEXT($D2,"dd-mmm-yyyy")," ",$E2," ",$G2) | I2: =IF(Investments_Import!C2="","",Investments_Import!C2) | J2: =IF(Investments_Import!D2="","",Investments_Import!D2) | K2: =IF($B2="","",$J2*1) | L2: =IF(Investments_Import!E2="","",Investments_Import!E2) | M2: =IF($L2="","",$L2*1) | N2: =IF(Investments_Import!F2="","",Investments_Import!F2) | O2: =IF($N2="","",$N2*1) | P2: =IF(Investments_Import!G2="","",Investments_Import!G2) | Q2: =IF(Investments_Import!H2="","",Investments_Import!H2) | R2: =IF($Q2="","",IF($Q2="USD",$P2,$P2*$J2)) | S2: =IF($R2="","",$R2*1) | U2: =IF(Mining_Import!A2="","",Mining_Import!A2) | V2: =IF(U2="","",U2*1) | W2: =V2 | X2: =IFERROR(INT($W2),"") | Y2: =$X2 | Z2: =IF(Mining_Import!B2="","",Mining_Import!B2) | AA2: =IF(Mining_Import!$C2="","",Mining_Import!$C2) | AB2: =IFERROR($AA2*1,"") | AC2: =IF($Y2>Dashboard!$Q$19,$AB2,"") | AD2: =IFERROR($AB2*$BU$19,"") | AE2: =IF(Mining_Import!D2="","",Mining_Import!D2) | AF2: =IF(Mining_Import!E2="","",Mining_Import!E2) | AG2: =IF(Mining_Import!F2="","",Mining_Import!F2) | AH2: =IF(Mining_Import!G2="","",Mining_Import!G2) | AI2: =IF(Mining_Import!H2="","",Mining_Import!H2) | AJ2: =IF(Mining_Import!I2="","",Mining_Import!I2) | AL2: =IFERROR(INDEX($E$2:$E$2500, MATCH(0, INDEX(COUNTIF($AL$1:AL1, $E$2:$E$2500), 0, 0), 0)), "") | AM2: =IF(Calculator!$AL2="","",LEFT(Calculator!$AL2, LEN(Calculator!$AL2)-3)) | AN2: {=IF($AL2="","",MAX(IF($E$2:$E$2500=$AL2,$C$2:$C$2500)))} | AO2: =IF($AN2="","",(TEXT($AN2,"dd-mmm-yyyy")&" "&$AL2&" "&"1")) | AP2: =$AO2 | AQ2: =IF($AL2="","",VLOOKUP($AO2, $H:$K, 3, 0)) | AR2: =IF($AQ2="","",$AQ2*1) | AS2: =IF($AL2="","",SUMIFS($O:$O,$E:$E,$AL2,$I:$I,"BUY")) | AT2: =IF($AL2="","",SUMIFS($O:$O,$E:$E,$AL2,$I:$I,"SELL")) | AU2: =IF($AL2="","",SUMIF($E:$E,$AL2,$S:$S)) | AV2: =IF($AL2="","",SUMIFS($M:$M,$E:$E,$AL2,$I:$I,"BUY")) | AW2: =IF($AL2="","",SUMIFS($M:$M,$E:$E,$AL2,$I:$I,"SELL")) | AX2: =IF($AZ2=1,$AV2-$AW2,"") | AY2: =$AM2 | AZ2: =IF($AY2="","",IFERROR(VLOOKUP($AP2,$BG$2:$BH$13,2, FALSE),"")) | BA2: =IF($AZ2=1, "CURRENT","") | BB2: =IF($AW2=0,"",IFERROR($AS2-$BD2,"")) | BC2: =IFERROR(IF($BA2="CURRENT",(($AT2-$BB2)-$AU2),IF($AW2=0,"",($AT2-$AS2)-$AU2)),"") | BD2: =IF($BA2="CURRENT",($AX2*$AR2),"") | BF2: =CONCATENATE(TEXT(Dashboard!$Q8,"dd-mmm-yyyy")," ",Dashboard!$P8,"USD"," ",1) -> 05-Feb-2021 USDUSD 1 | BG2: =IF($BF2="00-Jan-1900 USD 1","",$BF2) -> 05-Feb-2021 USDUSD 1 | BH2: 1 | BI2: =SUMIF($I:$I,"BUY",$O:$O) -> 0 | BJ2: =SUMIF($I:$I,"SELL",$O:$O) -> 0 | BK2: =$BI$2-(SUM($BD:$BD)) -> 0 | BL2: =SUM(($BC$2:$BC$50),(-$BM$2)) -> 0 | BM2: =SUM($S:$S) -> 0 | BN2: =(SUMPRODUCT(1/COUNTIF($F$2:$F$2500,$F$2:$F$2500))-1) -> 4.9515947e-14 | BO2: =COUNTIF(Calculator!$W:$W,">0") -> 0 | BP2: =SUM($AB:$AB) -> 0 | BQ2: =SUM($AC:$AC) -> 0 | BR2: http://coinmarketcap.com/currencies/litecoin/ | BS2: =IF(Stock_Connector!B2="","",Stock_Connector!B2) -> LTC | BT2: =IF(Stock_Connector!C2="","",Stock_Connector!C2) -> 151.8 | BU2: =IF(Stock_Connector!C2="","",Stock_Connector!C2) -> 151.8 | BV2: =IF(Stock_Connector!E2="","",Stock_Connector!E2) | BW2: =IF(Stock_Connector!D2="","",Stock_Connector!D2) -> -0.056322268 | BY2: =Y2 | BZ2: =AB2 | CA2: =IFERROR(VLOOKUP($BY2,Account_Value!$C$2:$F$2500,4,0),"") | CB2: =IF(BZ2="","",BZ2*CA2) | CC2: =IF($BZ2="","",SUM($BZ$2:$BZ2)) | CD2: =IF($BZ2="","",$CA2*(SUM($BZ$2:$BZ2)))
A3: =IF($B3="","",$A2+1) | B3: =IF(Investments_Import!A3="","",Investments_Import!A3) | C3: =IF(B3="","",B3*1) | D3: =$C3 | E3: =IF(Investments_Import!B3="","",Investments_Import!B3) | F3: =CONCATENATE(TEXT($D3,"dd-mmm-yyyy")," ",$E3) | G3: =IF($B3="","",COUNTIF($F$2:$F3,$F3)) | H3: =CONCATENATE(TEXT($D3,"dd-mmm-yyyy")," ",$E3," ",$G3) | I3: =IF(Investments_Import!C3="","",Investments_Import!C3) | J3: =IF(Investments_Import!D3="","",Investments_Import!D3) | K3: =IF($B3="","",$J3*1) | L3: =IF(Investments_Import!E3="","",Investments_Import!E3) | M3: =IF($L3="","",$L3*1) | N3: =IF(Investments_Import!F3="","",Investments_Import!F3) | O3: =IF($N3="","",$N3*1) | P3: =IF(Investments_Import!G3="","",Investments_Import!G3) | Q3: =IF(Investments_Import!H3="","",Investments_Import!H3) | R3: =IF($Q3="","",IF($Q3="USD",$P3,$P3*$J3)) | S3: =IF($R3="","",$R3*1) | U3: =IF(Mining_Import!A3="","",Mining_Import!A3) | V3: =IF(U3="","",U3*1) | W3: =V3 | X3: =IFERROR(INT($W3),"") | Y3: =$X3 | Z3: =IF(Mining_Import!B3="","",Mining_Import!B3) | AA3: =IF(Mining_Import!$C3="","",Mining_Import!$C3) | AB3: =IFERROR($AA3*1,"") | AC3: =IF($Y3>Dashboard!$Q$19,$AB3,"") | AD3: =IFERROR($AB3*$BU$19,"") | AE3: =IF(Mining_Import!D3="","",Mining_Import!D3) | AF3: =IF(Mining_Import!E3="","",Mining_Import!E3) | AG3: =IF(Mining_Import!F3="","",Mining_Import!F3) | AH3: =IF(Mining_Import!G3="","",Mining_Import!G3) | AI3: =IF(Mining_Import!H3="","",Mining_Import!H3) | AJ3: =IF(Mining_Import!I3="","",Mining_Import!I3) | AL3: =IFERROR(INDEX($E$2:$E$2500, MATCH(0, INDEX(COUNTIF($AL$1:AL2, $E$2:$E$2500), 0, 0), 0)), "") | AM3: =IF(Calculator!$AL3="","",LEFT(Calculator!$AL3, LEN(Calculator!$AL3)-3)) | AN3: {=IF($AL3="","",MAX(IF($E$2:$E$2500=$AL3,$C$2:$C$2500)))} | AO3: =IF($AN3="","",(TEXT($AN3,"dd-mmm-yyyy")&" "&$AL3&" "&"1")) | AP3: =$AO3 | AQ3: =IF($AL3="","",VLOOKUP($AO3, $H:$K, 3, 0)) | AR3: =IF($AQ3="","",$AQ3*1) | AS3: =IF($AL3="","",SUMIFS($O:$O,$E:$E,$AL3,$I:$I,"BUY")) | AT3: =IF($AL3="","",SUMIFS($O:$O,$E:$E,$AL3,$I:$I,"SELL")) | AU3: =IF($AL3="","",SUMIF($E:$E,$AL3,$S:$S)) | AV3: =IF($AL3="","",SUMIFS($M:$M,$E:$E,$AL3,$I:$I,"BUY")) | AW3: =IF($AL3="","",SUMIFS($M:$M,$E:$E,$AL3,$I:$I,"SELL")) | AX3: =IF($AZ3=1,$AV3-$AW3,"") | AY3: =$AM3 | AZ3: =IF($AY3="","",IFERROR(VLOOKUP($AP3,$BG$2:$BH$13,2, FALSE),"")) | BA3: =IF($AZ3=1, "CURRENT","") | BB3: =IF($AW3=0,"",IFERROR($AS3-$BD3,"")) | BC3: =IFERROR(IF($BA3="CURRENT",(($AT3-$BB3)-$AU3),IF($AW3=0,"",($AT3-$AS3)-$AU3)),"") | BD3: =IF($BA3="CURRENT",($AX3*$AR3),"") | BF3: =CONCATENATE(TEXT(Dashboard!$Q9,"dd-mmm-yyyy")," ",Dashboard!$P9,"USD"," ",1) -> 00-Jan-1900 USD 1 | BG3: =IF($BF3="00-Jan-1900 USD 1","",$BF3) | BH3: 1 | BR3: https://coinmarketcap.com/currencies/zcash/ | BS3: =IF(Stock_Connector!B3="","",Stock_Connector!B3) -> ZEC | BT3: =IF(Stock_Connector!C3="","",Stock_Connector!C3) -> 92.93284 | BU3: =IF(Stock_Connector!C3="","",Stock_Connector!C3) -> 92.93284 | BV3: =IF(Stock_Connector!E3="","",Stock_Connector!E3) | BW3: =IF(Stock_Connector!D3="","",Stock_Connector!D3) -> -0.046495885 | BY3: =Y3 | BZ3: =AB3 | CA3: =IFERROR(VLOOKUP($BY3,Account_Value!$C$2:$F$2500,4,0),"") | CB3: =IF(BZ3="","",BZ3*CA3) | CC3: =IF($BZ3="","",SUM($BZ$2:$BZ3)) | CD3: =IF($BZ3="","",$CA3*(SUM($BZ$2:$BZ3)))
A4: =IF($B4="","",$A3+1) | B4: =IF(Investments_Import!A4="","",Investments_Import!A4) | C4: =IF(B4="","",B4*1) | D4: =$C4 | E4: =IF(Investments_Import!B4="","",Investments_Import!B4) | F4: =CONCATENATE(TEXT($D4,"dd-mmm-yyyy")," ",$E4) | G4: =IF($B4="","",COUNTIF($F$2:$F4,$F4)) | H4: =CONCATENATE(TEXT($D4,"dd-mmm-yyyy")," ",$E4," ",$G4) | I4: =IF(Investments_Import!C4="","",Investments_Import!C4) | J4: =IF(Investments_Import!D4="","",Investments_Import!D4) | K4: =IF($B4="","",$J4*1) | L4: =IF(Investments_Import!E4="","",Investments_Import!E4) | M4: =IF($L4="","",$L4*1) | N4: =IF(Investments_Import!F4="","",Investments_Import!F4) | O4: =IF($N4="","",$N4*1) | P4: =IF(Investments_Import!G4="","",Investments_Import!G4) | Q4: =IF(Investments_Import!H4="","",Investments_Import!H4) | R4: =IF($Q4="","",IF($Q4="USD",$P4,$P4*$J4)) | S4: =IF($R4="","",$R4*1) | U4: =IF(Mining_Import!A4="","",Mining_Import!A4) | V4: =IF(U4="","",U4*1) | W4: =V4 | X4: =IFERROR(INT($W4),"") | Y4: =$X4 | Z4: =IF(Mining_Import!B4="","",Mining_Import!B4) | AA4: =IF(Mining_Import!$C4="","",Mining_Import!$C4) | AB4: =IFERROR($AA4*1,"") | AC4: =IF($Y4>Dashboard!$Q$19,$AB4,"") | AD4: =IFERROR($AB4*$BU$19,"") | AE4: =IF(Mining_Import!D4="","",Mining_Import!D4) | AF4: =IF(Mining_Import!E4="","",Mining_Import!E4) | AG4: =IF(Mining_Import!F4="","",Mining_Import!F4) | AH4: =IF(Mining_Import!G4="","",Mining_Import!G4) | AI4: =IF(Mining_Import!H4="","",Mining_Import!H4) | AJ4: =IF(Mining_Import!I4="","",Mining_Import!I4) | AL4: =IFERROR(INDEX($E$2:$E$2500, MATCH(0, INDEX(COUNTIF($AL$1:AL3, $E$2:$E$2500), 0, 0), 0)), "") | AM4: =IF(Calculator!$AL4="","",LEFT(Calculator!$AL4, LEN(Calculator!$AL4)-3)) | AN4: {=IF($AL4="","",MAX(IF($E$2:$E$2500=$AL4,$C$2:$C$2500)))} | AO4: =IF($AN4="","",(TEXT($AN4,"dd-mmm-yyyy")&" "&$AL4&" "&"1")) | AP4: =$AO4 | AQ4: =IF($AL4="","",VLOOKUP($AO4, $H:$K, 3, 0)) | AR4: =IF($AQ4="","",$AQ4*1) | AS4: =IF($AL4="","",SUMIFS($O:$O,$E:$E,$AL4,$I:$I,"BUY")) | AT4: =IF($AL4="","",SUMIFS($O:$O,$E:$E,$AL4,$I:$I,"SELL")) | AU4: =IF($AL4="","",SUMIF($E:$E,$AL4,$S:$S)) | AV4: =IF($AL4="","",SUMIFS($M:$M,$E:$E,$AL4,$I:$I,"BUY")) | AW4: =IF($AL4="","",SUMIFS($M:$M,$E:$E,$AL4,$I:$I,"SELL")) | AX4: =IF($AZ4=1,$AV4-$AW4,"") | AY4: =$AM4 | AZ4: =IF($AY4="","",IFERROR(VLOOKUP($AP4,$BG$2:$BH$13,2, FALSE),"")) | BA4: =IF($AZ4=1, "CURRENT","") | BB4: =IF($AW4=0,"",IFERROR($AS4-$BD4,"")) | BC4: =IFERROR(IF($BA4="CURRENT",(($AT4-$BB4)-$AU4),IF($AW4=0,"",($AT4-$AS4)-$AU4)),"") | BD4: =IF($BA4="CURRENT",($AX4*$AR4),"") | BF4: =CONCATENATE(TEXT(Dashboard!$Q10,"dd-mmm-yyyy")," ",Dashboard!$P10,"USD"," ",1) -> 00-Jan-1900 USD 1 | BG4: =IF($BF4="00-Jan-1900 USD 1","",$BF4) | BH4: 1 | BR4: https://coinmarketcap.com/currencies/ethereum-classic/ | BS4: =IF(Stock_Connector!B4="","",Stock_Connector!B4) -> ETC | BT4: =IF(Stock_Connector!C4="","",Stock_Connector!C4) -> 8.326 | BU4: =IF(Stock_Connector!C4="","",Stock_Connector!C4) -> 8.326 | BV4: =IF(Stock_Connector!E4="","",Stock_Connector!E4) | BW4: =IF(Stock_Connector!D4="","",Stock_Connector!D4) -> -0.035896248 | BY4: =Y4 | BZ4: =AB4 | CA4: =IFERROR(VLOOKUP($BY4,Account_Value!$C$2:$F$2500,4,0),"") | CB4: =IF(BZ4="","",BZ4*CA4) | CC4: =IF($BZ4="","",SUM($BZ$2:$BZ4)) | CD4: =IF($BZ4="","",$CA4*(SUM($BZ$2:$BZ4)))
A5: =IF($B5="","",$A4+1) | B5: =IF(Investments_Import!A5="","",Investments_Import!A5) | C5: =IF(B5="","",B5*1) | D5: =$C5 | E5: =IF(Investments_Import!B5="","",Investments_Import!B5) | F5: =CONCATENATE(TEXT($D5,"dd-mmm-yyyy")," ",$E5) | G5: =IF($B5="","",COUNTIF($F$2:$F5,$F5)) | H5: =CONCATENATE(TEXT($D5,"dd-mmm-yyyy")," ",$E5," ",$G5) | I5: =IF(Investments_Import!C5="","",Investments_Import!C5) | J5: =IF(Investments_Import!D5="","",Investments_Import!D5) | K5: =IF($B5="","",$J5*1) | L5: =IF(Investments_Import!E5="","",Investments_Import!E5) | M5: =IF($L5="","",$L5*1) | N5: =IF(Investments_Import!F5="","",Investments_Import!F5) | O5: =IF($N5="","",$N5*1) | P5: =IF(Investments_Import!G5="","",Investments_Import!G5) | Q5: =IF(Investments_Import!H5="","",Investments_Import!H5) | R5: =IF($Q5="","",IF($Q5="USD",$P5,$P5*$J5)) | S5: =IF($R5="","",$R5*1) | U5: =IF(Mining_Import!A5="","",Mining_Import!A5) | V5: =IF(U5="","",U5*1) | W5: =V5 | X5: =IFERROR(INT($W5),"") | Y5: =$X5 | Z5: =IF(Mining_Import!B5="","",Mining_Import!B5) | AA5: =IF(Mining_Import!$C5="","",Mining_Import!$C5) | AB5: =IFERROR($AA5*1,"") | AC5: =IF($Y5>Dashboard!$Q$19,$AB5,"") | AD5: =IFERROR($AB5*$BU$19,"") | AE5: =IF(Mining_Import!D5="","",Mining_Import!D5) | AF5: =IF(Mining_Import!E5="","",Mining_Import!E5) | AG5: =IF(Mining_Import!F5="","",Mining_Import!F5) | AH5: =IF(Mining_Import!G5="","",Mining_Import!G5) | AI5: =IF(Mining_Import!H5="","",Mining_Import!H5) | AJ5: =IF(Mining_Import!I5="","",Mining_Import!I5) | AL5: =IFERROR(INDEX($E$2:$E$2500, MATCH(0, INDEX(COUNTIF($AL$1:AL4, $E$2:$E$2500), 0, 0), 0)), "") | AM5: =IF(Calculator!$AL5="","",LEFT(Calculator!$AL5, LEN(Calculator!$AL5)-3)) | AN5: {=IF($AL5="","",MAX(IF($E$2:$E$2500=$AL5,$C$2:$C$2500)))} | AO5: =IF($AN5="","",(TEXT($AN5,"dd-mmm-yyyy")&" "&$AL5&" "&"1")) | AP5: =$AO5 | AQ5: =IF($AL5="","",VLOOKUP($AO5, $H:$K, 3, 0)) | AR5: =IF($AQ5="","",$AQ5*1) | AS5: =IF($AL5="","",SUMIFS($O:$O,$E:$E,$AL5,$I:$I,"BUY")) | AT5: =IF($AL5="","",SUMIFS($O:$O,$E:$E,$AL5,$I:$I,"SELL")) | AU5: =IF($AL5="","",SUMIF($E:$E,$AL5,$S:$S)) | AV5: =IF($AL5="","",SUMIFS($M:$M,$E:$E,$AL5,$I:$I,"BUY")) | AW5: =IF($AL5="","",SUMIFS($M:$M,$E:$E,$AL5,$I:$I,"SELL")) | AX5: =IF($AZ5=1,$AV5-$AW5,"") | AY5: =$AM5 | AZ5: =IF($AY5="","",IFERROR(VLOOKUP($AP5,$BG$2:$BH$13,2, FALSE),"")) | BA5: =IF($AZ5=1, "CURRENT","") | BB5: =IF($AW5=0,"",IFERROR($AS5-$BD5,"")) | BC5: =IFERROR(IF($BA5="CURRENT",(($AT5-$BB5)-$AU5),IF($AW5=0,"",($AT5-$AS5)-$AU5)),"") | BD5: =IF($BA5="CURRENT",($AX5*$AR5),"") | BF5: =CONCATENATE(TEXT(Dashboard!$Q11,"dd-mmm-yyyy")," ",Dashboard!$P11,"USD"," ",1) -> 00-Jan-1900 USD 1 | BG5: =IF($BF5="00-Jan-1900 USD 1","",$BF5) | BH5: 1 | BR5: https://coinmarketcap.com/currencies/icon/ | BS5: =IF(Stock_Connector!B5="","",Stock_Connector!B5) -> ICX | BT5: =IF(Stock_Connector!C5="","",Stock_Connector!C5) -> 0.8524516 | BU5: =IF(Stock_Connector!C5="","",Stock_Connector!C5) -> 0.8524516 | BV5: =IF(Stock_Connector!E5="","",Stock_Connector!E5) | BW5: =IF(Stock_Connector!D5="","",Stock_Connector!D5) -> 0.087359535 | BY5: =Y5 | BZ5: =AB5 | CA5: =IFERROR(VLOOKUP($BY5,Account_Value!$C$2:$F$2500,4,0),"") | CB5: =IF(BZ5="","",BZ5*CA5) | CC5: =IF($BZ5="","",SUM($BZ$2:$BZ5)) | CD5: =IF($BZ5="","",$CA5*(SUM($BZ$2:$BZ5)))
A6: =IF($B6="","",$A5+1) | B6: =IF(Investments_Import!A6="","",Investments_Import!A6) | C6: =IF(B6="","",B6*1) | D6: =$C6 | E6: =IF(Investments_Import!B6="","",Investments_Import!B6) | F6: =CONCATENATE(TEXT($D6,"dd-mmm-yyyy")," ",$E6) | G6: =IF($B6="","",COUNTIF($F$2:$F6,$F6)) | H6: =CONCATENATE(TEXT($D6,"dd-mmm-yyyy")," ",$E6," ",$G6) | I6: =IF(Investments_Import!C6="","",Investments_Import!C6) | J6: =IF(Investments_Import!D6="","",Investments_Import!D6) | K6: =IF($B6="","",$J6*1) | L6: =IF(Investments_Import!E6="","",Investments_Import!E6) | M6: =IF($L6="","",$L6*1) | N6: =IF(Investments_Import!F6="","",Investments_Import!F6) | O6: =IF($N6="","",$N6*1) | P6: =IF(Investments_Import!G6="","",Investments_Import!G6) | Q6: =IF(Investments_Import!H6="","",Investments_Import!H6) | R6: =IF($Q6="","",IF($Q6="USD",$P6,$P6*$J6)) | S6: =IF($R6="","",$R6*1) | U6: =IF(Mining_Import!A6="","",Mining_Import!A6) | V6: =IF(U6="","",U6*1) | W6: =V6 | X6: =IFERROR(INT($W6),"") | Y6: =$X6 | Z6: =IF(Mining_Import!B6="","",Mining_Import!B6) | AA6: =IF(Mining_Import!$C6="","",Mining_Import!$C6) | AB6: =IFERROR($AA6*1,"") | AC6: =IF($Y6>Dashboard!$Q$19,$AB6,"") | AD6: =IFERROR($AB6*$BU$19,"") | AE6: =IF(Mining_Import!D6="","",Mining_Import!D6) | AF6: =IF(Mining_Import!E6="","",Mining_Import!E6) | AG6: =IF(Mining_Import!F6="","",Mining_Import!F6) | AH6: =IF(Mining_Import!G6="","",Mining_Import!G6) | AI6: =IF(Mining_Import!H6="","",Mining_Import!H6) | AJ6: =IF(Mining_Import!I6="","",Mining_Import!I6) | AL6: =IFERROR(INDEX($E$2:$E$2500, MATCH(0, INDEX(COUNTIF($AL$1:AL5, $E$2:$E$2500), 0, 0), 0)), "") | AM6: =IF(Calculator!$AL6="","",LEFT(Calculator!$AL6, LEN(Calculator!$AL6)-3)) | AN6: {=IF($AL6="","",MAX(IF($E$2:$E$2500=$AL6,$C$2:$C$2500)))} | AO6: =IF($AN6="","",(TEXT($AN6,"dd-mmm-yyyy")&" "&$AL6&" "&"1")) | AP6: =$AO6 | AQ6: =IF($AL6="","",VLOOKUP($AO6, $H:$K, 3, 0)) | AR6: =IF($AQ6="","",$AQ6*1) | AS6: =IF($AL6="","",SUMIFS($O:$O,$E:$E,$AL6,$I:$I,"BUY")) | AT6: =IF($AL6="","",SUMIFS($O:$O,$E:$E,$AL6,$I:$I,"SELL")) | AU6: =IF($AL6="","",SUMIF($E:$E,$AL6,$S:$S)) | AV6: =IF($AL6="","",SUMIFS($M:$M,$E:$E,$AL6,$I:$I,"BUY")) | AW6: =IF($AL6="","",SUMIFS($M:$M,$E:$E,$AL6,$I:$I,"SELL")) | AX6: =IF($AZ6=1,$AV6-$AW6,"") | AY6: =$AM6 | AZ6: =IF($AY6="","",IFERROR(VLOOKUP($AP6,$BG$2:$BH$13,2, FALSE),"")) | BA6: =IF($AZ6=1, "CURRENT","") | BB6: =IF($AW6=0,"",IFERROR($AS6-$BD6,"")) | BC6: =IFERROR(IF($BA6="CURRENT",(($AT6-$BB6)-$AU6),IF($AW6=0,"",($AT6-$AS6)-$AU6)),"") | BD6: =IF($BA6="CURRENT",($AX6*$AR6),"") | BF6: =CONCATENATE(TEXT(Dashboard!$Q12,"dd-mmm-yyyy")," ",Dashboard!$P12,"USD"," ",1) -> 00-Jan-1900 USD 1 | BG6: =IF($BF6="00-Jan-1900 USD 1","",$BF6) | BH6: 1 | BR6: https://coinmarketcap.com/currencies/bitcoin-cash/ | BS6: =IF(Stock_Connector!B6="","",Stock_Connector!B6) -> BCH | BT6: =IF(Stock_Connector!C6="","",Stock_Connector!C6) -> 454.29 | BU6: =IF(Stock_Connector!C6="","",Stock_Connector!C6) -> 454.29 | BV6: =IF(Stock_Connector!E6="","",Stock_Connector!E6) | BW6: =IF(Stock_Connector!D6="","",Stock_Connector!D6) -> -0.054114267 | BY6: =Y6 | BZ6: =AB6 | CA6: =IFERROR(VLOOKUP($BY6,Account_Value!$C$2:$F$2500,4,0),"") | CB6: =IF(BZ6="","",BZ6*CA6) | CC6: =IF($BZ6="","",SUM($BZ$2:$BZ6)) | CD6: =IF($BZ6="","",$CA6*(SUM($BZ$2:$BZ6)))
A7: =IF($B7="","",$A6+1) | B7: =IF(Investments_Import!A7="","",Investments_Import!A7) | C7: =IF(B7="","",B7*1) | D7: =$C7 | E7: =IF(Investments_Import!B7="","",Investments_Import!B7) | F7: =CONCATENATE(TEXT($D7,"dd-mmm-yyyy")," ",$E7) | G7: =IF($B7="","",COUNTIF($F$2:$F7,$F7)) | H7: =CONCATENATE(TEXT($D7,"dd-mmm-yyyy")," ",$E7," ",$G7) | I7: =IF(Investments_Import!C7="","",Investments_Import!C7) | J7: =IF(Investments_Import!D7="","",Investments_Import!D7) | K7: =IF($B7="","",$J7*1) | L7: =IF(Investments_Import!E7="","",Investments_Import!E7) | M7: =IF($L7="","",$L7*1) | N7: =IF(Investments_Import!F7="","",Investments_Import!F7) | O7: =IF($N7="","",$N7*1) | P7: =IF(Investments_Import!G7="","",Investments_Import!G7) | Q7: =IF(Investments_Import!H7="","",Investments_Import!H7) | R7: =IF($Q7="","",IF($Q7="USD",$P7,$P7*$J7)) | S7: =IF($R7="","",$R7*1) | U7: =IF(Mining_Import!A7="","",Mining_Import!A7) | V7: =IF(U7="","",U7*1) | W7: =V7 | X7: =IFERROR(INT($W7),"") | Y7: =$X7 | Z7: =IF(Mining_Import!B7="","",Mining_Import!B7) | AA7: =IF(Mining_Import!$C7="","",Mining_Import!$C7) | AB7: =IFERROR($AA7*1,"") | AC7: =IF($Y7>Dashboard!$Q$19,$AB7,"") | AD7: =IFERROR($AB7*$BU$19,"") | AE7: =IF(Mining_Import!D7="","",Mining_Import!D7) | AF7: =IF(Mining_Import!E7="","",Mining_Import!E7) | AG7: =IF(Mining_Import!F7="","",Mining_Import!F7) | AH7: =IF(Mining_Import!G7="","",Mining_Import!G7) | AI7: =IF(Mining_Import!H7="","",Mining_Import!H7) | AJ7: =IF(Mining_Import!I7="","",Mining_Import!I7) | AL7: =IFERROR(INDEX($E$2:$E$2500, MATCH(0, INDEX(COUNTIF($AL$1:AL6, $E$2:$E$2500), 0, 0), 0)), "") | AM7: =IF(Calculator!$AL7="","",LEFT(Calculator!$AL7, LEN(Calculator!$AL7)-3)) | AN7: {=IF($AL7="","",MAX(IF($E$2:$E$2500=$AL7,$C$2:$C$2500)))} | AO7: =IF($AN7="","",(TEXT($AN7,"dd-mmm-yyyy")&" "&$AL7&" "&"1")) | AP7: =$AO7 | AQ7: =IF($AL7="","",VLOOKUP($AO7, $H:$K, 3, 0)) | AR7: =IF($AQ7="","",$AQ7*1) | AS7: =IF($AL7="","",SUMIFS($O:$O,$E:$E,$AL7,$I:$I,"BUY")) | AT7: =IF($AL7="","",SUMIFS($O:$O,$E:$E,$AL7,$I:$I,"SELL")) | AU7: =IF($AL7="","",SUMIF($E:$E,$AL7,$S:$S)) | AV7: =IF($AL7="","",SUMIFS($M:$M,$E:$E,$AL7,$I:$I,"BUY")) | AW7: =IF($AL7="","",SUMIFS($M:$M,$E:$E,$AL7,$I:$I,"SELL")) | AX7: =IF($AZ7=1,$AV7-$AW7,"") | AY7: =$AM7 | AZ7: =IF($AY7="","",IFERROR(VLOOKUP($AP7,$BG$2:$BH$13,2, FALSE),"")) | BA7: =IF($AZ7=1, "CURRENT","") | BB7: =IF($AW7=0,"",IFERROR($AS7-$BD7,"")) | BC7: =IFERROR(IF($BA7="CURRENT",(($AT7-$BB7)-$AU7),IF($AW7=0,"",($AT7-$AS7)-$AU7)),"") | BD7: =IF($BA7="CURRENT",($AX7*$AR7),"") | BF7: =CONCATENATE(TEXT(Dashboard!$Q13,"dd-mmm-yyyy")," ",Dashboard!$P13,"USD"," ",1) -> 00-Jan-1900 USD 1 | BG7: =IF($BF7="00-Jan-1900 USD 1","",$BF7) | BH7: 1 | BR7: https://coinmarketcap.com/currencies/qtum/ | BS7: =IF(Stock_Connector!B7="","",Stock_Connector!B7) -> QTUM | BT7: =IF(Stock_Connector!C7="","",Stock_Connector!C7) -> 4.359355 | BU7: =IF(Stock_Connector!C7="","",Stock_Connector!C7) -> 4.359355 | BV7: =IF(Stock_Connector!E7="","",Stock_Connector!E7) | BW7: =IF(Stock_Connector!D7="","",Stock_Connector!D7) -> 0.14460765 | BY7: =Y7 | BZ7: =AB7 | CA7: =IFERROR(VLOOKUP($BY7,Account_Value!$C$2:$F$2500,4,0),"") | CB7: =IF(BZ7="","",BZ7*CA7) | CC7: =IF($BZ7="","",SUM($BZ$2:$BZ7)) | CD7: =IF($BZ7="","",$CA7*(SUM($BZ$2:$BZ7)))
A8: =IF($B8="","",$A7+1) | B8: =IF(Investments_Import!A8="","",Investments_Import!A8) | C8: =IF(B8="","",B8*1) | D8: =$C8 | E8: =IF(Investments_Import!B8="","",Investments_Import!B8) | F8: =CONCATENATE(TEXT($D8,"dd-mmm-yyyy")," ",$E8) | G8: =IF($B8="","",COUNTIF($F$2:$F8,$F8)) | H8: =CONCATENATE(TEXT($D8,"dd-mmm-yyyy")," ",$E8," ",$G8) | I8: =IF(Investments_Import!C8="","",Investments_Import!C8) | J8: =IF(Investments_Import!D8="","",Investments_Import!D8) | K8: =IF($B8="","",$J8*1) | L8: =IF(Investments_Import!E8="","",Investments_Import!E8) | M8: =IF($L8="","",$L8*1) | N8: =IF(Investments_Import!F8="","",Investments_Import!F8) | O8: =IF($N8="","",$N8*1) | P8: =IF(Investments_Import!G8="","",Investments_Import!G8) | Q8: =IF(Investments_Import!H8="","",Investments_Import!H8) | R8: =IF($Q8="","",IF($Q8="USD",$P8,$P8*$J8)) | S8: =IF($R8="","",$R8*1) | U8: =IF(Mining_Import!A8="","",Mining_Import!A8) | V8: =IF(U8="","",U8*1) | W8: =V8 | X8: =IFERROR(INT($W8),"") | Y8: =$X8 | Z8: =IF(Mining_Import!B8="","",Mining_Import!B8) | AA8: =IF(Mining_Import!$C8="","",Mining_Import!$C8) | AB8: =IFERROR($AA8*1,"") | AC8: =IF($Y8>Dashboard!$Q$19,$AB8,"") | AD8: =IFERROR($AB8*$BU$19,"") | AE8: =IF(Mining_Import!D8="","",Mining_Import!D8) | AF8: =IF(Mining_Import!E8="","",Mining_Import!E8) | AG8: =IF(Mining_Import!F8="","",Mining_Import!F8) | AH8: =IF(Mining_Import!G8="","",Mining_Import!G8) | AI8: =IF(Mining_Import!H8="","",Mining_Import!H8) | AJ8: =IF(Mining_Import!I8="","",Mining_Import!I8) | AL8: =IFERROR(INDEX($E$2:$E$2500, MATCH(0, INDEX(COUNTIF($AL$1:AL7, $E$2:$E$2500), 0, 0), 0)), "") | AM8: =IF(Calculator!$AL8="","",LEFT(Calculator!$AL8, LEN(Calculator!$AL8)-3)) | AN8: {=IF($AL8="","",MAX(IF($E$2:$E$2500=$AL8,$C$2:$C$2500)))} | AO8: =IF($AN8="","",(TEXT($AN8,"dd-mmm-yyyy")&" "&$AL8&" "&"1")) | AP8: =$AO8 | AQ8: =IF($AL8="","",VLOOKUP($AO8, $H:$K, 3, 0)) | AR8: =IF($AQ8="","",$AQ8*1) | AS8: =IF($AL8="","",SUMIFS($O:$O,$E:$E,$AL8,$I:$I,"BUY")) | AT8: =IF($AL8="","",SUMIFS($O:$O,$E:$E,$AL8,$I:$I,"SELL")) | AU8: =IF($AL8="","",SUMIF($E:$E,$AL8,$S:$S)) | AV8: =IF($AL8="","",SUMIFS($M:$M,$E:$E,$AL8,$I:$I,"BUY")) | AW8: =IF($AL8="","",SUMIFS($M:$M,$E:$E,$AL8,$I:$I,"SELL")) | AX8: =IF($AZ8=1,$AV8-$AW8,"") | AY8: =$AM8 | AZ8: =IF($AY8="","",IFERROR(VLOOKUP($AP8,$BG$2:$BH$13,2, FALSE),"")) | BA8: =IF($AZ8=1, "CURRENT","") | BB8: =IF($AW8=0,"",IFERROR($AS8-$BD8,"")) | BC8: =IFERROR(IF($BA8="CURRENT",(($AT8-$BB8)-$AU8),IF($AW8=0,"",($AT8-$AS8)-$AU8)),"") | BD8: =IF($BA8="CURRENT",($AX8*$AR8),"") | BF8: =CONCATENATE(TEXT(Dashboard!$Q14,"dd-mmm-yyyy")," ",Dashboard!$P14,"USD"," ",1) -> 00-Jan-1900 USD 1 | BG8: =IF($BF8="00-Jan-1900 USD 1","",$BF8) | BH8: 1 | BR8: https://coinmarketcap.com/currencies/neo/ | BS8: =IF(Stock_Connector!B8="","",Stock_Connector!B8) -> NEO | BT8: =IF(Stock_Connector!C8="","",Stock_Connector!C8) -> 24.84482 | BU8: =IF(Stock_Connector!C8="","",Stock_Connector!C8) -> 24.84482 | BV8: =IF(Stock_Connector!E8="","",Stock_Connector!E8) | BW8: =IF(Stock_Connector!D8="","",Stock_Connector!D8) -> 0.010400552 | BY8: =Y8 | BZ8: =AB8 | CA8: =IFERROR(VLOOKUP($BY8,Account_Value!$C$2:$F$2500,4,0),"") | CB8: =IF(BZ8="","",BZ8*CA8) | CC8: =IF($BZ8="","",SUM($BZ$2:$BZ8)) | CD8: =IF($BZ8="","",$CA8*(SUM($BZ$2:$BZ8)))
